2024-03-02 00:21:47,446 INFO    StreamThr :76436 [internal.py:wandb_internal():86] W&B internal server running at pid: 76436, started at: 2024-03-02 00:21:47.446234
2024-03-02 00:21:47,447 DEBUG   HandlerThread:76436 [handler.py:handle_request():146] handle_request: status
2024-03-02 00:21:47,459 INFO    WriterThread:76436 [datastore.py:open_for_write():87] open: /Users/karansampath/Documents/GitHub/teaching_arithmetic_division/wandb/run-20240302_002147-bbhv6tft/run-bbhv6tft.wandb
2024-03-02 00:21:47,459 DEBUG   SenderThread:76436 [sender.py:send():382] send: header
2024-03-02 00:21:47,479 DEBUG   SenderThread:76436 [sender.py:send():382] send: run
2024-03-02 00:21:47,641 ERROR   SenderThread:76436 [internal_api.py:execute():373] 403 response executing GraphQL.
2024-03-02 00:21:47,641 ERROR   SenderThread:76436 [internal_api.py:execute():374] {"errors":[{"message":"permission denied","path":["upsertBucket"],"extensions":{"code":"PERMISSION_ERROR"}}],"data":{"upsertBucket":null}}
2024-03-02 00:21:47,641 ERROR   SenderThread:76436 [sender.py:send_run():987] It appears that you do not have permission to access the requested resource. Please reach out to the project owner to grant you access. If you have the correct permissions, verify that there are no issues with your networking setup.(Error 403: Forbidden)
Traceback (most recent call last):
  File "/Library/Frameworks/Python.framework/Versions/3.11/lib/python3.11/site-packages/wandb/sdk/lib/retry.py", line 131, in __call__
    result = self._call_fn(*args, **kwargs)
             ^^^^^^^^^^^^^^^^^^^^^^^^^^^^^^
  File "/Library/Frameworks/Python.framework/Versions/3.11/lib/python3.11/site-packages/wandb/sdk/internal/internal_api.py", line 369, in execute
    return self.client.execute(*args, **kwargs)  # type: ignore
           ^^^^^^^^^^^^^^^^^^^^^^^^^^^^^^^^^^^^
  File "/Library/Frameworks/Python.framework/Versions/3.11/lib/python3.11/site-packages/wandb/vendor/gql-0.2.0/wandb_gql/client.py", line 52, in execute
    result = self._get_result(document, *args, **kwargs)
             ^^^^^^^^^^^^^^^^^^^^^^^^^^^^^^^^^^^^^^^^^^^
  File "/Library/Frameworks/Python.framework/Versions/3.11/lib/python3.11/site-packages/wandb/vendor/gql-0.2.0/wandb_gql/client.py", line 60, in _get_result
    return self.transport.execute(document, *args, **kwargs)
           ^^^^^^^^^^^^^^^^^^^^^^^^^^^^^^^^^^^^^^^^^^^^^^^^^
  File "/Library/Frameworks/Python.framework/Versions/3.11/lib/python3.11/site-packages/wandb/sdk/lib/gql_request.py", line 59, in execute
    request.raise_for_status()
  File "/Library/Frameworks/Python.framework/Versions/3.11/lib/python3.11/site-packages/requests/models.py", line 1021, in raise_for_status
    raise HTTPError(http_error_msg, response=self)
requests.exceptions.HTTPError: 403 Client Error: Forbidden for url: https://api.wandb.ai/graphql

During handling of the above exception, another exception occurred:

Traceback (most recent call last):
  File "/Library/Frameworks/Python.framework/Versions/3.11/lib/python3.11/site-packages/wandb/sdk/internal/sender.py", line 985, in send_run
    self._init_run(run, config_value_dict)
  File "/Library/Frameworks/Python.framework/Versions/3.11/lib/python3.11/site-packages/wandb/sdk/internal/sender.py", line 1027, in _init_run
    server_run, inserted, server_messages = self._api.upsert_run(
                                            ^^^^^^^^^^^^^^^^^^^^^
  File "/Library/Frameworks/Python.framework/Versions/3.11/lib/python3.11/site-packages/wandb/apis/normalize.py", line 73, in wrapper
    raise err
  File "/Library/Frameworks/Python.framework/Versions/3.11/lib/python3.11/site-packages/wandb/apis/normalize.py", line 41, in wrapper
    return func(*args, **kwargs)
           ^^^^^^^^^^^^^^^^^^^^^
  File "/Library/Frameworks/Python.framework/Versions/3.11/lib/python3.11/site-packages/wandb/sdk/internal/internal_api.py", line 2216, in upsert_run
    response = self.gql(
               ^^^^^^^^^
  File "/Library/Frameworks/Python.framework/Versions/3.11/lib/python3.11/site-packages/wandb/sdk/internal/internal_api.py", line 341, in gql
    ret = self._retry_gql(
          ^^^^^^^^^^^^^^^^
  File "/Library/Frameworks/Python.framework/Versions/3.11/lib/python3.11/site-packages/wandb/sdk/lib/retry.py", line 147, in __call__
    retry_timedelta_triggered = check_retry_fn(e)
                                ^^^^^^^^^^^^^^^^^
  File "/Library/Frameworks/Python.framework/Versions/3.11/lib/python3.11/site-packages/wandb/util.py", line 965, in check_retry_fn
    return fallback_retry_fn(e)
           ^^^^^^^^^^^^^^^^^^^^
  File "/Library/Frameworks/Python.framework/Versions/3.11/lib/python3.11/site-packages/wandb/util.py", line 907, in no_retry_auth
    raise CommError(
wandb.errors.CommError: It appears that you do not have permission to access the requested resource. Please reach out to the project owner to grant you access. If you have the correct permissions, verify that there are no issues with your networking setup.(Error 403: Forbidden)
2024-03-02 00:21:47,725 DEBUG   HandlerThread:76436 [handler.py:handle_request():146] handle_request: shutdown
2024-03-02 00:21:47,725 INFO    HandlerThread:76436 [handler.py:finish():869] shutting down handler
2024-03-02 00:21:48,484 INFO    WriterThread:76436 [datastore.py:close():296] close: /Users/karansampath/Documents/GitHub/teaching_arithmetic_division/wandb/run-20240302_002147-bbhv6tft/run-bbhv6tft.wandb
2024-03-02 00:21:48,653 INFO    SenderThread:76436 [sender.py:finish():1572] shutting down sender
